Workbook

Sheet Instructions
B2: Ultimate DSA Placement Dashboard v3.0
B3: Principal Software Edition - Dynamic Knowledge & Analytics Engine
B5: Workbook Overview
B6: This workbook represents a premium placement preparation engine with 307 problems. Version 3.0 integrates a Mistakes Database, Pattern Encyclopedia, a live Dynamic Search Engine, and a Balanced Dynamic Revision prioritizing Weakness, ROI, and Confidence.
B8: Revision Color Indicators
B9: Status | C9: Rule / Delay | D9: Suggested Schedule
B10: Green | C10: Solved under target time without hints. | D10: Review in 30 days.
B11: Yellow | C11: Solved using hints or took between 15-30 minutes. | D11: Review in 7 days.
B12: Red | C12: Could not solve, required looking up solution, or took >30 mins. | D12: Review in 2 days.
B14: Dashboard Quick Navigation Shortcuts
B15: Sheet Link | C15: Core Utility | D15: Key Dynamic Formula Features
B16: Search Engine | C16: Perform complex multi-variable filters on the entire problem catalog. | D16: Nested FILTER with boolean multipliers
B17: Smart Recommendations | C17: Review customized, live suggestions for Weak Patterns, Forgotten Problems, and target companies. | D17: CHOOSEROWS, TEXTJOIN, SORTBY

Sheet Settings
A1: CS Topics | B1: Difficulties | C1: Statuses | D1: Patterns | E1: Companies | F1: Confidences | G1: Mistake Types | H1: Date | I1: Solved | J1: DSA Topics
A2: OOP | B2: Easy | C2: Green | D2: Arrays | E2: Accenture | F2: 1 | G2: Off by one | H2: =TODAY() -> 0 | I2: =IF(COUNTIF(tblMasterDatabase[Attempt Date], H2)>0, 1, 0) -> 0 | J2: Arrays
A3: DBMS | B3: Medium | C3: Yellow | D3: BFS | E3: Infosys | F3: 2 | G3: Overflow | H3: =H2-1 -> 0 | I3: =IF(COUNTIF(tblMasterDatabase[Attempt Date], H3)>0, 1, 0) -> 0 | J3: Hashing
A4: SQL | B4: Hard | C4: Red | D4: BST | E4: Capgemini | F4: 3 | G4: Wrong Binary Search | H4: =H3-1 -> 0 | I4: =IF(COUNTIF(tblMasterDatabase[Attempt Date], H4)>0, 1, 0) -> 0 | J4: Strings
A5: Operating Systems | D5: Backtracking | E5: Cognizant | F5: 4 | G5: Wrong Sliding Window | H5: =H4-1 -> 0 | I5: =IF(COUNTIF(tblMasterDatabase[Attempt Date], H5)>0, 1, 0) -> 0 | J5: Binary Search
A6: Computer Networks | D6: Binary Search | E6: Deloitte | F6: 5 | G6: Wrong DFS | H6: =H5-1 -> 0 | I6: =IF(COUNTIF(tblMasterDatabase[Attempt Date], H6)>0, 1, 0) -> 0 | J6: Sliding Window
D7: Binary Search on Answer | E7: EY | G7: Boundary Case | H7: =H6-1 -> 0 | I7: =IF(COUNTIF(tblMasterDatabase[Attempt Date], H7)>0, 1, 0) -> 0 | J7: Two Pointer
D8: Bit Manipulation | E8: Oracle | G8: Recursion Error | H8: =H7-1 -> 0 | I8: =IF(COUNTIF(tblMasterDatabase[Attempt Date], H8)>0, 1, 0) -> 0 | J8: Linked List
D9: DFS | E9: JPMC | G9: Null Pointer | H9: =H8-1 -> 0 | I9: =IF(COUNTIF(tblMasterDatabase[Attempt Date], H9)>0, 1, 0) -> 0 | J9: Stack & Queue
D10: Dynamic Programming | E10: LTIMindtree | G10: Forgot Observation | H10: =H9-1 -> 0 | I10: =IF(COUNTIF(tblMasterDatabase[Attempt Date], H10)>0, 1, 0) -> 0 | J10: Greedy
D11: Greedy | E11: Virtusa | H11: =H10-1 -> 0 | I11: =IF(COUNTIF(tblMasterDatabase[Attempt Date], H11)>0, 1, 0) -> 0 | J11: Binary Trees
D12: HashMap | H12: =H11-1 -> 0 | I12: =IF(COUNTIF(tblMasterDatabase[Attempt Date], H12)>0, 1, 0) -> 0 | J12: BST
D13: Heap | H13: =H12-1 -> 0 | I13: =IF(COUNTIF(tblMasterDatabase[Attempt Date], H13)>0, 1, 0) -> 0 | J13: Heap
D14: Intervals | H14: =H13-1 -> 0 | I14: =IF(COUNTIF(tblMasterDatabase[Attempt Date], H14)>0, 1, 0) -> 0 | J14: Graphs
D15: Kadane | H15: =H14-1 -> 0 | I15: =IF(COUNTIF(tblMasterDatabase[Attempt Date], H15)>0, 1, 0) -> 0 | J15: Dynamic Programming
D16: Linked List | H16: =H15-1 -> 0 | I16: =IF(COUNTIF(tblMasterDatabase[Attempt Date], H16)>0, 1, 0) -> 0 | J16: Bit Manipulation
D17: Matrix | H17: =H16-1 -> 0 | I17: =IF(COUNTIF(tblMasterDatabase[Attempt Date], H17)>0, 1, 0) -> 0 | J17: Math/Misc
D18: Monotonic Stack | H18: =H17-1 -> 0 | I18: =IF(COUNTIF(tblMasterDatabase[Attempt Date], H18)>0, 1, 0) -> 0
D19: Prefix Sum | H19: =H18-1 -> 0 | I19: =IF(COUNTIF(tblMasterDatabase[Attempt Date], H19)>0, 1, 0) -> 0
D20: Queue | H20: =H19-1 -> 0 | I20: =IF(COUNTIF(tblMasterDatabase[Attempt Date], H20)>0, 1, 0) -> 0
D21: Recursion | H21: =H20-1 -> 0 | I21: =IF(COUNTIF(tblMasterDatabase[Attempt Date], H21)>0, 1, 0) -> 0
D22: Sliding Window | H22: =H21-1 -> 0 | I22: =IF(COUNTIF(tblMasterDatabase[Attempt Date], H22)>0, 1, 0) -> 0
D23: Topological Sort | H23: =H22-1 -> 0 | I23: =IF(COUNTIF(tblMasterDatabase[Attempt Date], H23)>0, 1, 0) -> 0
D24: Trees | H24: =H23-1 -> 0 | I24: =IF(COUNTIF(tblMasterDatabase[Attempt Date], H24)>0, 1, 0) -> 0
D25: Trie | H25: =H24-1 -> 0 | I25: =IF(COUNTIF(tblMasterDatabase[Attempt Date], H25)>0, 1, 0) -> 0
D26: Two Pointer | H26: =H25-1 -> 0 | I26: =IF(COUNTIF(tblMasterDatabase[Attempt Date], H26)>0, 1, 0) -> 0
D27: Union Find | H27: =H26-1 -> 0 | I27: =IF(COUNTIF(tblMasterDatabase[Attempt Date], H27)>0, 1, 0) -> 0
H28: =H27-1 -> 0 | I28: =IF(COUNTIF(tblMasterDatabase[Attempt Date], H28)>0, 1, 0) -> 0
H29: =H28-1 -> 0 | I29: =IF(COUNTIF(tblMasterDatabase[Attempt Date], H29)>0, 1, 0) -> 0
H30: =H29-1 -> 0 | I30: =IF(COUNTIF(tblMasterDatabase[Attempt Date], H30)>0, 1, 0) -> 0
H31: =H30-1 -> 0 | I31: =IF(COUNTIF(tblMasterDatabase[Attempt Date], H31)>0, 1, 0) -> 0

Sheet Pattern Encyclopedia
A1: Disjoint Algorithms & DSA Coding Pattern Encyclopedia
A3: Pattern Name | B3: Recognition Clues | C3: When to Use | D3: When NOT to Use | E3: Common Mistakes | F3: Time Complexity | G3: Space Complexity | H3: Representative Problems | I3: Top Interview Questions | J3: ROI | K3: Campus Frequency | L3: Expected Difficulty
A4: Arrays | B4: Contiguous elements, index lookup, static size, subarray/subsequence. | C4: Direct mapping, fixed bounds, fast random access required. | D4: Frequent insertions/deletions at start or middle. | E4: Out of bounds index, incorrect subarray sizing, integer overflow. | F4: O(1) lookup, O(N) traversal | G4: O(1) extra space | H4: Two Sum, Maximum Subarray | I4: Kadane's Algorithm, Merge Intervals | J4: 10 | K4: ★★★★★ | L4: Easy to Medium
A5: HashMap | B5: O(1) search, frequency counting, check existence, lookup key. | C5: Fast element mapping, count occurrences, anagram checks. | D5: Inputs are sorted and space complexity is O(1) constrained. | E5: Ignoring hash collisions, modifying map while iterating. | F5: O(1) average lookup/insert | G5: O(N) space | H5: Contains Duplicate, Group Anagrams | I5: Subarray Sum Equals K, Two Sum | J5: 10 | K5: ★★★★★ | L5: Easy to Medium
A6: Sliding Window | B6: Contiguous subarray/substring, min/max length, sum/target constraint. | C6: Linear scans of sub-sequences with size bounds. | D6: Non-contiguous subsets or dynamic sorting required. | E6: Off-by-one window size calculations, wrong shrink loop boundary. | F6: O(N) | G6: O(1) or O(K) where K is character set size | H6: Longest Substring Without Repeating Characters, Minimum Window Substring | I6: Subarrays with K Different Integers | J6: 9 | K6: ★★★★★ | L6: Medium to Hard
A7: Two Pointer | B7: Sorted array, pair search, partition, fast/slow traversal, dynamic boundaries. | C7: Shrinking/expanding search space from ends, list cycle detection. | D7: Unsorted array where sorting is not feasible. | E7: Infinite pointer increment loops, pointer crossings. | F7: O(N) | G7: O(1) | H7: 3Sum, Container With Most Water | I7: Trapping Rain Water, Two Sum II | J7: 10 | K7: ★★★★★ | L7: Easy to Medium
A8: Prefix Sum | B8: Subarray sums, range queries, multiple lookups, cumulative calculations. | C8: O(1) range sum queries, prefix product, prefix XOR. | D8: Array values are updated frequently (use Segment Tree instead). | E8: Off-by-one index offsets, overflow on large accumulations. | F8: O(1) query, O(N) precomputation | G8: O(N) | H8: Product of Array Except Self, Subarray Sum Equals K | I8: Subarray Sums Divisible by K | J8: 9 | K8: ★★★★☆ | L8: Medium
A9: Kadane | B9: Max subarray sum, max subarray product, global vs local maximums. | C9: Continuous subarray optimizing maximum sum/product. | D9: Non-contiguous sub-sequences or dynamic sum bounds. | E9: Resetting max sum to 0 when negative numbers are valid outputs. | F9: O(N) | G9: O(1) | H9: Maximum Subarray, Maximum Product Subarray | I9: Maximum Subarray Sum | J9: 10 | K9: ★★★★★ | L9: Easy to Medium
A10: Binary Search | B10: Sorted array, O(log N) runtime constraint, search index, search insertion point. | C10: Finding target in partitioned monotonic sequence. | D10: Unsorted input, linked lists (slow random access). | E10: Integer overflow in (l+r)/2, search boundary update off-by-one. | F10: O(log N) | G10: O(1) | H10: Search in Rotated Sorted Array, First and Last Position | I10: Median of Two Sorted Arrays | J10: 10 | K10: ★★★★★ | L10: Medium
A11: Binary Search on Answer | B11: Minimize the maximum value, maximize the minimum value, feasibility helper. | C11: Output space is monotonic and bounded, checking feasibility is O(N). | D11: Output space is discontinuous or non-monotonic. | E11: Choosing incorrect low/high bounds, incorrect feasibility logic. | F11: O(N log M) where M is search space | G11: O(1) | H11: Koko Eating Bananas, Book Allocation Problem | I11: Aggressive Cows, Split Array Largest Sum | J11: 9 | K11: ★★★★★ | L11: Medium to Hard
A12: Greedy | B12: Local optimal choice, sorting by attributes, standard interval scheduling. | C12: Problem possesses greedy choice property and optimal substructure. | D12: Requires backtracking or checking all combinations (use DP). | E12: Failing to prove greedy choice correctness, wrong sorting comparator. | F12: O(N log N) due to sorting | G12: O(1) or O(N) | H12: Jump Game, Assign Cookies | I12: Gas Station, Merge Intervals | J12: 9 | K12: ★★★★☆ | L12: Medium
A13: Intervals | B13: Overlapping ranges, meetings, intervals, scheduling, merge ranges. | C13: Input represents ranges with start/end boundaries. | D13: No overlapping relation needed. | E13: Sorting by end time instead of start time (or vice versa), border conditions. | F13: O(N log N) | G13: O(N) | H13: Merge Intervals, Insert Interval | I13: Meeting Rooms II, Non-overlapping Intervals | J13: 10 | K13: ★★★★★ | L13: Medium
A14: Monotonic Stack | B14: Next greater element, next smaller element, histogram, stock span. | C14: Compare element with previous contiguous elements, O(N) constraint. | D14: General stack problems where order is arbitrary. | E14: Popping on wrong comparator, empty stack check missing. | F14: O(N) | G14: O(N) | H14: Next Greater Element, Daily Temperatures | I14: Largest Rectangle in Histogram, Trapping Rain Water | J14: 9 | K14: ★★★★☆ | L14: Medium to Hard
A15: Queue | B15: FIFO, sliding window maximum, BFS traversal, scheduling. | C15: Process items in order of arrival, level-order tree scans. | D15: LIFO ordering or random index updates. | E15: Queue size modification during iterations, queue overflow. | F15: O(1) push/pop | G15: O(N) | H15: Implement Queue using Stacks, Sliding Window Maximum | I15: Sliding Window Maximum, Rotting Oranges | J15: 8 | K15: ★★★★☆ | L15: Easy to Medium
... A29: Matrix | B29: 2D Grid, cell traversal, coordinate shifts, boundary walls. | C29: Grid traversal, cell state updates, row/column operations. | D29: Linear sequence calculations. | E29: Out of bounds cell index, incorrect row/column boundaries. | F29: O(M * N) | G29: O(1) or O(M * N) | H29: Set Matrix Zeroes, Spiral Matrix | I29: Search a 2D Matrix, Rotate Image | J29: 9 | K29: ★★★★★ | L29: Medium

Sheet Master Problem Database
A1: Problem ID | B1: Problem Name | C1: Topic | D1: Pattern | E1: Difficulty | F1: Expected Time | G1: ROI | H1: Campus Frequency | I1: Company Frequency | J1: Recognition Clues | K1: Common Mistakes | L1: Time Complexity | M1: Space Complexity | N1: Company Tags | O1: Striver Link | P1: LeetCode Link | Q1: GFG Link | R1: YouTube Link | S1: Attempt Date | T1: Time Taken | U1: Hint Used | V1: Confidence | W1: Status | X1: Revision Count | Y1: Next Revision | Z1: Revision Priority | AA1: Notes
A2: 1 | B2: Two Sum | C2: Arrays | D2: HashMap | E2: Easy | F2: 20 | G2: 10 | H2: ★★★★★ | I2: ★★★★★ | J2: O(1) search, frequency counting, check existence, lookup key. | K2: Ignoring hash collisions, modifying map while iterating. | L2: O(1) average lookup/insert | M2: O(N) space | N2: Accenture, Deloitte, Infosys DSE, JPMC | O2: Striver | P2: LeetCode | Q2: GFG | R2: YouTube | Y2: =IF(S2="", "", IF(W2="Green", S2+30, IF(W2="Yellow", S2+7, IF(W2="Red", S2+2, "")))) -> 0 | Z2: =IF(Y2="", "", (Y2-TODAY()) * 50 - V2 * 10 - G2 * 5 + IF(W2="Red", -20, IF(W2="Yellow", -10, 0)) - IFERROR(INDEX(Analytics!$F$5:$F$20, MATCH(C2, Analytics!$A$5:$A$20, 0)) * 5, 0) + MOD(A2, 7)) -> 0
A3: 2 | B3: Best Time to Buy and Sell Stock | C3: Arrays | D3: Two Pointer | E3: Easy | F3: 20 | G3: 10 | H3: ★★★★★ | I3: ★★★★★ | J3: Sorted array, pair search, partition, fast/slow traversal, dynamic boundaries. | K3: Infinite pointer increment loops, pointer crossings. | L3: O(N) | M3: O(1) | N3: Deloitte, EY, Oracle, JPMC | O3: Striver | P3: LeetCode | Q3: GFG | R3: YouTube | Y3: =IF(S3="", "", IF(W3="Green", S3+30, IF(W3="Yellow", S3+7, IF(W3="Red", S3+2, "")))) -> 0 | Z3: =IF(Y3="", "", (Y3-TODAY()) * 50 - V3 * 10 - G3 * 5 + IF(W3="Red", -20, IF(W3="Yellow", -10, 0)) - IFERROR(INDEX(Analytics!$F$5:$F$20, MATCH(C3, Analytics!$A$5:$A$20, 0)) * 5, 0) + MOD(A3, 7)) -> 0
A4: 3 | B4: Majority Element | C4: Arrays | D4: HashMap | E4: Easy | F4: 20 | G4: 9 | H4: ★★★★☆ | I4: ★★★★★ | J4: O(1) search, frequency counting, check existence, lookup key. | K4: Ignoring hash collisions, modifying map while iterating. | L4: O(1) average lookup/insert | M4: O(N) space | N4: Accenture, Cognizant Next, EY | O4: Striver | P4: LeetCode | Q4: GFG | R4: YouTube | Y4: =IF(S4="", "", IF(W4="Green", S4+30, IF(W4="Yellow", S4+7, IF(W4="Red", S4+2, "")))) -> 0 | Z4: =IF(Y4="", "", (Y4-TODAY()) * 50 - V4 * 10 - G4 * 5 + IF(W4="Red", -20, IF(W4="Yellow", -10, 0)) - IFERROR(INDEX(Analytics!$F$5:$F$20, MATCH(C4, Analytics!$A$5:$A$20, 0)) * 5, 0) + MOD(A4, 7)) -> 0
A5: 4 | B5: Move Zeroes | C5: Arrays | D5: Two Pointer | E5: Easy | F5: 20 | G5: 8 | H5: ★★★★☆ | I5: ★★★★☆ | J5: Sorted array, pair search, partition, fast/slow traversal, dynamic boundaries. | K5: Infinite pointer increment loops, pointer crossings. | L5: O(N) | M5: O(1) | N5: Infosys DSE, Capgemini | O5: Striver | P5: LeetCode | Q5: GFG | R5: YouTube | Y5: =IF(S5="", "", IF(W5="Green", S5+30, IF(W5="Yellow", S5+7, IF(W5="Red", S5+2, "")))) -> 0 | Z5: =IF(Y5="", "", (Y5-TODAY()) * 50 - V5 * 10 - G5 * 5 + IF(W5="Red", -20, IF(W5="Yellow", -10, 0)) - IFERROR(INDEX(Analytics!$F$5:$F$20, MATCH(C5, Analytics!$A$5:$A$20, 0)) * 5, 0) + MOD(A5, 7)) -> 0
A6: 5 | B6: Merge Sorted Array | C6: Arrays | D6: Two Pointer | E6: Easy | F6: 20 | G6: 9 | H6: ★★★★★ | I6: ★★★★★ | J6: Sorted array, pair search, partition, fast/slow traversal, dynamic boundaries. | K6: Infinite pointer increment loops, pointer crossings. | L6: O(N) | M6: O(1) | N6: Oracle, JPMC, Virtusa | O6: Striver | P6: LeetCode | Q6: GFG | R6: YouTube | Y6: =IF(S6="", "", IF(W6="Green", S6+30, IF(W6="Yellow", S6+7, IF(W6="Red", S6+2, "")))) -> 0 | Z6: =IF(Y6="", "", (Y6-TODAY()) * 50 - V6 * 10 - G6 * 5 + IF(W6="Red", -20, IF(W6="Yellow", -10, 0)) - IFERROR(INDEX(Analytics!$F$5:$F$20, MATCH(C6, Analytics!$A$5:$A$20, 0)) * 5, 0) + MOD(A6, 7)) -> 0
A7: 6 | B7: Pascal's Triangle | C7: Arrays | D7: Bit Manipulation | E7: Easy | F7: 20 | G7: 8 | H7: ★★★☆☆ | I7: ★★★★☆ | J7: Bitwise XOR, AND, OR, shifting, power of two, count set bits. | K7: Operator precedence errors (always use parentheses around bitwise ops). | L7: O(1) | M7: O(1) | N7: Deloitte, Capgemini | O7: Striver | P7: LeetCode | Q7: GFG | R7: YouTube | Y7: =IF(S7="", "", IF(W7="Green", S7+30, IF(W7="Yellow", S7+7, IF(W7="Red", S7+2, "")))) -> 0 | Z7: =IF(Y7="", "", (Y7-TODAY()) * 50 - V7 * 10 - G7 * 5 + IF(W7="Red", -20, IF(W7="Yellow", -10, 0)) - IFERROR(INDEX(Analytics!$F$5:$F$20, MATCH(C7, Analytics!$A$5:$A$20, 0)) * 5, 0) + MOD(A7, 7)) -> 0
A8: 7 | B8: Sort Colors | C8: Arrays | D8: Two Pointer | E8: Medium | F8: 40 | G8: 10 | H8: ★★★★★ | I8: ★★★★★ | J8: Sorted array, pair search, partition, fast/slow traversal, dynamic boundaries. | K8: Infinite pointer increment loops, pointer crossings. | L8: O(N) | M8: O(1) | N8: Accenture, Cognizant Next, Oracle, JPMC | O8: Striver | P8: LeetCode | Q8: GFG | R8: YouTube | Y8: =IF(S8="", "", IF(W8="Green", S8+30, IF(W8="Yellow", S8+7, IF(W8="Red", S8+2, "")))) -> 0 | Z8: =IF(Y8="", "", (Y8-TODAY()) * 50 - V8 * 10 - G8 * 5 + IF(W8="Red", -20, IF(W8="Yellow", -10, 0)) - IFERROR(INDEX(Analytics!$F$5:$F$20, MATCH(C8, Analytics!$A$5:$A$20, 0)) * 5, 0) + MOD(A8, 7)) -> 0
A9: 8 | B9: Maximum Subarray | C9: Arrays | D9: Kadane | E9: Medium | F9: 40 | G9: 10 | H9: ★★★★★ | I9: ★★★★★ | J9: Max subarray sum, max subarray product, global vs local maximums. | K9: Resetting max sum to 0 when negative numbers are valid outputs. | L9: O(N) | M9: O(1) | N9: EY, LTIMindtree, Oracle, JPMC | O9: Striver | P9: LeetCode | Q9: GFG | R9: YouTube | Y9: =IF(S9="", "", IF(W9="Green", S9+30, IF(W9="Yellow", S9+7, IF(W9="Red", S9+2, "")))) -> 0 | Z9: =IF(Y9="", "", (Y9-TODAY()) * 50 - V9 * 10 - G9 * 5 + IF(W9="Red", -20, IF(W9="Yellow", -10, 0)) - IFERROR(INDEX(Analytics!$F$5:$F$20, MATCH(C9, Analytics!$A$5:$A$20, 0)) * 5, 0) + MOD(A9, 7)) -> 0
A10: 9 | B10: Maximum Product Subarray | C10: Arrays | D10: Kadane | E10: Medium | F10: 40 | G10: 9 | H10: ★★★★☆ | I10: ★★★★★ | J10: Max subarray sum, max subarray product, global vs local maximums. | K10: Resetting max sum to 0 when negative numbers are valid outputs. | L10: O(N) | M10: O(1) | N10: Oracle, JPMC | O10: Striver | P10: LeetCode | Q10: GFG | R10: YouTube | Y10: =IF(S10="", "", IF(W10="Green", S10+30, IF(W10="Yellow", S10+7, IF(W10="Red", S10+2, "")))) -> 0 | Z10: =IF(Y10="", "", (Y10-TODAY()) * 50 - V10 * 10 - G10 * 5 + IF(W10="Red", -20, IF(W10="Yellow", -10, 0)) - IFERROR(INDEX(Analytics!$F$5:$F$20, MATCH(C10, Analytics!$A$5:$A$20, 0)) * 5, 0) + MOD(A10, 7)) -> 0
A11: 10 | B11: Merge Intervals | C11: Arrays | D11: Intervals | E11: Medium | F11: 40 | G11: 10 | H11: ★★★★★ | I11: ★★★★★ | J11: Overlapping ranges, meetings, intervals, scheduling, merge ranges. | K11: Sorting by end time instead of start time (or vice versa), border conditions. | L11: O(N log N) | M11: O(N) | N11: Deloitte, JPMC, Oracle, LTIMindtree | O11: Striver | P11: LeetCode | Q11: GFG | R11: YouTube | Y11: =IF(S11="", "", IF(W11="Green", S11+30, IF(W11="Yellow", S11+7, IF(W11="Red", S11+2, "")))) -> 0 | Z11: =IF(Y11="", "", (Y11-TODAY()) * 50 - V11 * 10 - G11 * 5 + IF(W11="Red", -20, IF(W11="Yellow", -10, 0)) - IFERROR(INDEX(Analytics!$F$5:$F$20, MATCH(C11, Analytics!$A$5:$A$20, 0)) * 5, 0) + MOD(A11, 7)) -> 0
A12: 11 | B12: Insert Interval | C12: Arrays | D12: Intervals | E12: Medium | F12: 40 | G12: 9 | H12: ★★★★☆ | I12: ★★★★★ | J12: Overlapping ranges, meetings, intervals, scheduling, merge ranges. | K12: Sorting by end time instead of start time (or vice versa), border conditions. | L12: O(N log N) | M12: O(N) | N12: JPMC, Capgemini | O12: Striver | P12: LeetCode | Q12: GFG | R12: YouTube | Y12: =IF(S12="", "", IF(W12="Green", S12+30, IF(W12="Yellow", S12+7, IF(W12="Red", S12+2, "")))) -> 0 | Z12: =IF(Y12="", "", (Y12-TODAY()) * 50 - V12 * 10 - G12 * 5 + IF(W12="Red", -20, IF(W12="Yellow", -10, 0)) - IFERROR(INDEX(Analytics!$F$5:$F$20, MATCH(C12, Analytics!$A$5:$A$20, 0)) * 5, 0) + MOD(A12, 7)) -> 0
A13: 12 | B13: Non-overlapping Intervals | C13: Arrays | D13: Intervals | E13: Medium | F13: 40 | G13: 8 | H13: ★★★★☆ | I13: ★★★★☆ | J13: Overlapping ranges, meetings, intervals, scheduling, merge ranges. | K13: Sorting by end time instead of start time (or vice versa), border conditions. | L13: O(N log N) | M13: O(N) | N13: EY, Oracle | O13: Striver | P13: LeetCode | Q13: GFG | R13: YouTube | Y13: =IF(S13="", "", IF(W13="Green", S13+30, IF(W13="Yellow", S13+7, IF(W13="Red", S13+2, "")))) -> 0 | Z13: =IF(Y13="", "", (Y13-TODAY()) * 50 - V13 * 10 - G13 * 5 + IF(W13="Red", -20, IF(W13="Yellow", -10, 0)) - IFERROR(INDEX(Analytics!$F$5:$F$20, MATCH(C13, Analytics!$A$5:$A$20, 0)) * 5, 0) + MOD(A13, 7)) -> 0
... A308: 307 | B308: Prime Factorization | C308: Math/Misc | D308: Bit Manipulation | E308: Easy | F308: 20 | G308: 8 | H308: ★★★★☆ | I308: ★★★★☆ | J308: Bitwise XOR, AND, OR, shifting, power of two, count set bits. | K308: Operator precedence errors (always use parentheses around bitwise ops). | L308: O(1) | M308: O(1) | N308: Virtusa | O308: Striver | P308: LeetCode | Q308: GFG | R308: YouTube | Y308: =IF(S308="", "", IF(W308="Green", S308+30, IF(W308="Yellow", S308+7, IF(W308="Red", S308+2, "")))) -> 0 | Z308: =IF(Y308="", "", (Y308-TODAY()) * 50 - V308 * 10 - G308 * 5 + IF(W308="Red", -20, IF(W308="Yellow", -10, 0)) - IFERROR(INDEX(Analytics!$F$5:$F$20, MATCH(C308, Analytics!$A$5:$A$20, 0)) * 5, 0) + MOD(A308, 7)) -> 0

Sheet Smart Recommendations
B2: Dynamic Placement Solve & Revision Recommendations
B3: Dynamic recommendations engine mapping weaknesses, forgotten problems, and high ROI patterns
B5: Today's Top 10 High-ROI Solve Recommendations | J5: Top 5 Weak Coding Patterns | Q5: Top 5 Forgotten Problems (Overdue) | X5: Top 5 High ROI Unsolved Problems
B6: ID | C6: Problem Name | D6: Topic | E6: Pattern | F6: Difficulty | G6: ROI | J6: Pattern Name | K6: Total | L6: Solved | M6: Completion % | N6: Avg Confidence | O6: Mastery | P6: Weakness | Q6: ID | R6: Problem Name | S6: Topic | T6: Pattern | U6: Status | V6: Next Revision | X6: ID | Y6: Problem Name | Z6: Topic | AA6: Pattern | AB6: Difficulty | AC6: ROI
B7: {=IFERROR(_xlfn.TAKE(_xlfn.SORTBY(_xlfn._xlws.FILTER(_xlfn.CHOOSECOLS(tblMasterDatabase, 1, 2, 3, 4, 5, 7), tblMasterDatabase[Status]=""), _xlfn._xlws.FILTER(tblMasterDatabase[ROI], tblMasterDatabase[Status]=""), -1), 10), "All solved!")} -> 0 | J7: {=IFERROR(_xlfn.TAKE(_xlfn.SORTBY(_xlfn._xlws.FILTER(_xlfn.CHOOSECOLS(tblPatternTracker, 1, 2, 3, 4, 5, 9, 10), tblPatternTracker[Solved]>0), _xlfn._xlws.FILTER(tblPatternTracker[Mastery Score], tblPatternTracker[Solved]>0), 1), 5), "None")} -> 0 | Q7: {=IFERROR(_xlfn.TAKE(_xlfn.SORTBY(_xlfn._xlws.FILTER(_xlfn.CHOOSECOLS(tblMasterDatabase, 1, 2, 3, 4, 23, 25), (tblMasterDatabase[Next Revision]<TODAY()) * (tblMasterDatabase[Status]<>"")), _xlfn._xlws.FILTER(tblMasterDatabase[Next Revision], (tblMasterDatabase[Next Revision]<TODAY()) * (tblMasterDatabase[Status]<>"")), 1), 5), "All revisions caught up!")} -> 0 | X7: {=IFERROR(_xlfn.TAKE(_xlfn.SORTBY(_xlfn._xlws.FILTER(_xlfn.CHOOSECOLS(tblMasterDatabase, 1, 2, 3, 4, 5, 7), (tblMasterDatabase[Status]="") * (tblMasterDatabase[ROI]>=9)), _xlfn._xlws.FILTER(tblMasterDatabase[ROI], (tblMasterDatabase[Status]="") * (tblMasterDatabase[ROI]>=9)), -1), 5), "No High ROI problems left!")} -> 0
B20: Top 5 Frequently Missed / Flagged Problems | J20: Top 5 Target Company Recommended Problems
B21: ID | C21: Problem Name | D21: Topic | E21: Pattern | F21: Status | G21: Revision Count | J21: ID | K21: Problem Name | L21: Topic | M21: Pattern | N21: Company Tags | O21: ROI
B22: {=IFERROR(_xlfn.TAKE(_xlfn.SORTBY(_xlfn._xlws.FILTER(_xlfn.CHOOSECOLS(tblMasterDatabase, 1, 2, 3, 4, 23, 24), (tblMasterDatabase[Status]="Red") + (tblMasterDatabase[Status]="Yellow")), _xlfn._xlws.FILTER(tblMasterDatabase[Revision Count], (tblMasterDatabase[Status]="Red") + (tblMasterDatabase[Status]="Yellow")), -1), 5), "No frequently missed problems!")} -> 0 | J22: {=IFERROR(_xlfn.TAKE(_xlfn.SORTBY(_xlfn._xlws.FILTER(_xlfn.CHOOSECOLS(tblMasterDatabase, 1, 2, 3, 4, 14, 7), (tblMasterDatabase[Status]="") * (tblMasterDatabase[Company Tags]<>"")), _xlfn._xlws.FILTER(tblMasterDatabase[ROI], (tblMasterDatabase[Status]="") * (tblMasterDatabase[Company Tags]<>"")), -1), 5), "No company recommendations!")} -> 0

Sheet Search Engine
B2: Interactive Database Search Engine & Quick Filters
B3: Quick Filter Preset: | C3: All
B5: Search Problem Name: | D5: Filter Topic: | F5: Filter Pattern: | H5: Filter Company:
B6: Min ROI Score (1-10): | D6: Filter Difficulty: | F6: Filter Confidence: | H6: Revision Overdue?:
B8: ID | C8: Problem Name | D8: Topic | E8: Pattern | F8: Difficulty | G8: Expected Time | H8: ROI | I8: Company Tags | J8: Status | K8: Confidence | L8: Next Revision
B9: {=IFERROR(_xlfn.CHOOSECOLS(_xlfn._xlws.FILTER(tblMasterDatabase, IF(C3="High ROI", (tblMasterDatabase[ROI]>=8)*(tblMasterDatabase[Status]=""), IF(C3="Needs Revision", (tblMasterDatabase[Next Revision]<=TODAY())*(tblMasterDatabase[Status]<>""), IF(C3="Overdue", (tblMasterDatabase[Next Revision]<TODAY())*(tblMasterDatabase[Status]<>""), IF(C3="Low Confidence", (tblMasterDatabase[Confidence]<=2)*(tblMasterDatabase[Confidence]<>""), IF(C3="Trees", (tblMasterDatabase[Topic]="Binary Trees")+(tblMasterDatabase[Topic]="BST"), IF(C3="Sliding Window", tblMasterDatabase[Pattern]="Sliding Window", IF(C3="Company Recommended", (tblMasterDatabase[Company Tags]<>"")*(tblMasterDatabase[Status]=""), 1))))))) * (C5="" + ISNUMBER(SEARCH(C5, tblMasterDatabase[Problem Name]))) * (E5="" + (tblMasterDatabase[Topic]=E5)) * (G5="" + (tblMasterDatabase[Pattern]=G5)) * (I5="" + ISNUMBER(SEARCH(I5, tblMasterDatabase[Company Tags]))) * (C6="" + (tblMasterDatabase[ROI]>=C6)) * (E6="" + (tblMasterDatabase[Difficulty]=E6)) * (G6="" + (tblMasterDatabase[Confidence]=G6)) * (I6="" + IF(I6="Yes", tblMasterDatabase[Next Revision]<=TODAY(), tblMasterDatabase[Next Revision]>TODAY()))), 1, 2, 3, 4, 5, 6, 7, 14, 23, 22, 25), "No problems match your filter/search criteria!")} -> 0

Sheet Today's Revision
B3: Overdue Revisions
B4: ID | C4: Problem Name | D4: Topic | E4: Pattern | F4: Difficulty | G4: Expected Time | H4: ROI | I4: Status | J4: Next Revision
B5: {=IFERROR(_xlfn.CHOOSECOLS(_xlfn.SORTBY(_xlfn._xlws.FILTER(tblMasterDatabase, (tblMasterDatabase[Next Revision]<TODAY()) * (tblMasterDatabase[Status]<>"")), _xlfn._xlws.FILTER(tblMasterDatabase[Revision Priority], (tblMasterDatabase[Next Revision]<TODAY()) * (tblMasterDatabase[Status]<>"")), 1), 1, 2, 3, 4, 5, 6, 7, 23, 25), "No overdue revisions!")} -> 0
B13: Due Today
B14: ID | C14: Problem Name | D14: Topic | E14: Pattern | F14: Difficulty | G14: Expected Time | H14: ROI | I14: Status | J14: Next Revision
B15: {=IFERROR(_xlfn.CHOOSECOLS(_xlfn.SORTBY(_xlfn._xlws.FILTER(tblMasterDatabase, (tblMasterDatabase[Next Revision]=TODAY()) * (tblMasterDatabase[Status]<>"")), _xlfn._xlws.FILTER(tblMasterDatabase[Revision Priority], (tblMasterDatabase[Next Revision]=TODAY()) * (tblMasterDatabase[Status]<>"")), 1), 1, 2, 3, 4, 5, 6, 7, 23, 25), "No revisions due today!")} -> 0
B23: Tomorrow
B24: ID | C24: Problem Name | D24: Topic | E24: Pattern | F24: Difficulty | G24: Expected Time | H24: ROI | I24: Status | J24: Next Revision
B25: {=IFERROR(_xlfn.CHOOSECOLS(_xlfn._xlws.FILTER(tblMasterDatabase, (tblMasterDatabase[Next Revision]=TODAY()+1) * (tblMasterDatabase[Status]<>"")), 1, 2, 3, 4, 5, 6, 7, 23, 25), "No revisions tomorrow!")} -> 0
B33: Upcoming (Next 7 Days)
B34: ID | C34: Problem Name | D34: Topic | E34: Pattern | F34: Difficulty | G34: Expected Time | H34: ROI | I34: Status | J34: Next Revision
B35: {=IFERROR(_xlfn.CHOOSECOLS(_xlfn._xlws.FILTER(tblMasterDatabase, (tblMasterDatabase[Next Revision]>TODAY()+1) * (tblMasterDatabase[Next Revision]<=TODAY()+7) * (tblMasterDatabase[Status]<>"")), 1, 2, 3, 4, 5, 6, 7, 23, 25), "No upcoming revisions!")} -> 0

Sheet Green Problems
A1: Green Problems - Spilled Live Feed
A3: Problem ID | B3: Problem Name | C3: Topic | D3: Pattern | E3: Difficulty | F3: Expected Time | G3: ROI | H3: Campus Frequency | I3: Company Frequency | J3: Recognition Clues | K3: Common Mistakes | L3: Time Complexity | M3: Space Complexity | N3: Company Tags | O3: Striver Link | P3: LeetCode Link | Q3: GFG Link | R3: YouTube Link | S3: Attempt Date | T3: Time Taken | U3: Hint Used | V3: Confidence | W3: Status | X3: Revision Count | Y3: Next Revision | Z3: Revision Priority | AA3: Notes
A4: {=IFERROR(_xlfn._xlws.FILTER(tblMasterDatabase, tblMasterDatabase[Status]="Green"), "No Green problems solved yet.")} -> 0

Sheet Yellow Problems
A1: Yellow Problems - Spilled Live Feed
A3: Problem ID | B3: Problem Name | C3: Topic | D3: Pattern | E3: Difficulty | F3: Expected Time | G3: ROI | H3: Campus Frequency | I3: Company Frequency | J3: Recognition Clues | K3: Common Mistakes | L3: Time Complexity | M3: Space Complexity | N3: Company Tags | O3: Striver Link | P3: LeetCode Link | Q3: GFG Link | R3: YouTube Link | S3: Attempt Date | T3: Time Taken | U3: Hint Used | V3: Confidence | W3: Status | X3: Revision Count | Y3: Next Revision | Z3: Revision Priority | AA3: Notes
A4: {=IFERROR(_xlfn._xlws.FILTER(tblMasterDatabase, tblMasterDatabase[Status]="Yellow"), "No Yellow problems solved yet.")} -> 0

Sheet Red Problems
A1: Red Problems - Spilled Live Feed
A3: Problem ID | B3: Problem Name | C3: Topic | D3: Pattern | E3: Difficulty | F3: Expected Time | G3: ROI | H3: Campus Frequency | I3: Company Frequency | J3: Recognition Clues | K3: Common Mistakes | L3: Time Complexity | M3: Space Complexity | N3: Company Tags | O3: Striver Link | P3: LeetCode Link | Q3: GFG Link | R3: YouTube Link | S3: Attempt Date | T3: Time Taken | U3: Hint Used | V3: Confidence | W3: Status | X3: Revision Count | Y3: Next Revision | Z3: Revision Priority | AA3: Notes
A4: {=IFERROR(_xlfn._xlws.FILTER(tblMasterDatabase, tblMasterDatabase[Status]="Red"), "No Red problems solved yet.")} -> 0

Sheet Pattern Tracker
A1: DSA Pattern Mastery Tracker & Analytics
A3: Pattern Name | B3: Total Problems | C3: Solved | D3: Completion % | E3: Average Confidence | F3: Average Time | G3: Hint Rate | H3: Revision Count | I3: Mastery Score | J3: Weakness
A4: Arrays | B4: =COUNTIF(tblMasterDatabase[Pattern], A4) -> 0 | C4: =COUNTIFS(tblMasterDatabase[Pattern], A4, tblMasterDatabase[Status], "<>") -> 0 | D4: =IF(B4=0, 0, C4/B4) -> 0 | E4: =IF(C4=0, 0, AVERAGEIFS(tblMasterDatabase[Confidence], tblMasterDatabase[Pattern], A4, tblMasterDatabase[Status], "<>")) -> 0 | F4: =IF(C4=0, 0, AVERAGEIFS(tblMasterDatabase[Time Taken], tblMasterDatabase[Pattern], A4, tblMasterDatabase[Status], "<>")) -> 0 | G4: =IF(C4=0, 0, COUNTIFS(tblMasterDatabase[Pattern], A4, tblMasterDatabase[Hint Used], "Yes") / C4) -> 0 | H4: =SUMIFS(tblMasterDatabase[Revision Count], tblMasterDatabase[Pattern], A4) -> 0 | I4: =D4 * E4 / 5 -> 0 | J4: =IF(C4=0, "Not Started", IF(E4<=2.5, "Weak (High Risk)", IF(E4<=3.5, "Medium", "Strong"))) -> 0
A5: BFS | B5: =COUNTIF(tblMasterDatabase[Pattern], A5) -> 0 | C5: =COUNTIFS(tblMasterDatabase[Pattern], A5, tblMasterDatabase[Status], "<>") -> 0 | D5: =IF(B5=0, 0, C5/B5) -> 0 | E5: =IF(C5=0, 0, AVERAGEIFS(tblMasterDatabase[Confidence], tblMasterDatabase[Pattern], A5, tblMasterDatabase[Status], "<>")) -> 0 | F5: =IF(C5=0, 0, AVERAGEIFS(tblMasterDatabase[Time Taken], tblMasterDatabase[Pattern], A5, tblMasterDatabase[Status], "<>")) -> 0 | G5: =IF(C5=0, 0, COUNTIFS(tblMasterDatabase[Pattern], A5, tblMasterDatabase[Hint Used], "Yes") / C5) -> 0 | H5: =SUMIFS(tblMasterDatabase[Revision Count], tblMasterDatabase[Pattern], A5) -> 0 | I5: =D5 * E5 / 5 -> 0 | J5: =IF(C5=0, "Not Started", IF(E5<=2.5, "Weak (High Risk)", IF(E5<=3.5, "Medium", "Strong"))) -> 0
A6: BST | B6: =COUNTIF(tblMasterDatabase[Pattern], A6) -> 0 | C6: =COUNTIFS(tblMasterDatabase[Pattern], A6, tblMasterDatabase[Status], "<>") -> 0 | D6: =IF(B6=0, 0, C6/B6) -> 0 | E6: =IF(C6=0, 0, AVERAGEIFS(tblMasterDatabase[Confidence], tblMasterDatabase[Pattern], A6, tblMasterDatabase[Status], "<>")) -> 0 | F6: =IF(C6=0, 0, AVERAGEIFS(tblMasterDatabase[Time Taken], tblMasterDatabase[Pattern], A6, tblMasterDatabase[Status], "<>")) -> 0 | G6: =IF(C6=0, 0, COUNTIFS(tblMasterDatabase[Pattern], A6, tblMasterDatabase[Hint Used], "Yes") / C6) -> 0 | H6: =SUMIFS(tblMasterDatabase[Revision Count], tblMasterDatabase[Pattern], A6) -> 0 | I6: =D6 * E6 / 5 -> 0 | J6: =IF(C6=0, "Not Started", IF(E6<=2.5, "Weak (High Risk)", IF(E6<=3.5, "Medium", "Strong"))) -> 0
A7: Backtracking | B7: =COUNTIF(tblMasterDatabase[Pattern], A7) -> 0 | C7: =COUNTIFS(tblMasterDatabase[Pattern], A7, tblMasterDatabase[Status], "<>") -> 0 | D7: =IF(B7=0, 0, C7/B7) -> 0 | E7: =IF(C7=0, 0, AVERAGEIFS(tblMasterDatabase[Confidence], tblMasterDatabase[Pattern], A7, tblMasterDatabase[Status], "<>")) -> 0 | F7: =IF(C7=0, 0, AVERAGEIFS(tblMasterDatabase[Time Taken], tblMasterDatabase[Pattern], A7, tblMasterDatabase[Status], "<>")) -> 0 | G7: =IF(C7=0, 0, COUNTIFS(tblMasterDatabase[Pattern], A7, tblMasterDatabase[Hint Used], "Yes") / C7) -> 0 | H7: =SUMIFS(tblMasterDatabase[Revision Count], tblMasterDatabase[Pattern], A7) -> 0 | I7: =D7 * E7 / 5 -> 0 | J7: =IF(C7=0, "Not Started", IF(E7<=2.5, "Weak (High Risk)", IF(E7<=3.5, "Medium", "Strong"))) -> 0
A8: Binary Search | B8: =COUNTIF(tblMasterDatabase[Pattern], A8) -> 0 | C8: =COUNTIFS(tblMasterDatabase[Pattern], A8, tblMasterDatabase[Status], "<>") -> 0 | D8: =IF(B8=0, 0, C8/B8) -> 0 | E8: =IF(C8=0, 0, AVERAGEIFS(tblMasterDatabase[Confidence], tblMasterDatabase[Pattern], A8, tblMasterDatabase[Status], "<>")) -> 0 | F8: =IF(C8=0, 0, AVERAGEIFS(tblMasterDatabase[Time Taken], tblMasterDatabase[Pattern], A8, tblMasterDatabase[Status], "<>")) -> 0 | G8: =IF(C8=0, 0, COUNTIFS(tblMasterDatabase[Pattern], A8, tblMasterDatabase[Hint Used], "Yes") / C8) -> 0 | H8: =SUMIFS(tblMasterDatabase[Revision Count], tblMasterDatabase[Pattern], A8) -> 0 | I8: =D8 * E8 / 5 -> 0 | J8: =IF(C8=0, "Not Started", IF(E8<=2.5, "Weak (High Risk)", IF(E8<=3.5, "Medium", "Strong"))) -> 0
A9: Binary Search on Answer | B9: =COUNTIF(tblMasterDatabase[Pattern], A9) -> 0 | C9: =COUNTIFS(tblMasterDatabase[Pattern], A9, tblMasterDatabase[Status], "<>") -> 0 | D9: =IF(B9=0, 0, C9/B9) -> 0 | E9: =IF(C9=0, 0, AVERAGEIFS(tblMasterDatabase[Confidence], tblMasterDatabase[Pattern], A9, tblMasterDatabase[Status], "<>")) -> 0 | F9: =IF(C9=0, 0, AVERAGEIFS(tblMasterDatabase[Time Taken], tblMasterDatabase[Pattern], A9, tblMasterDatabase[Status], "<>")) -> 0 | G9: =IF(C9=0, 0, COUNTIFS(tblMasterDatabase[Pattern], A9, tblMasterDatabase[Hint Used], "Yes") / C9) -> 0 | H9: =SUMIFS(tblMasterDatabase[Revision Count], tblMasterDatabase[Pattern], A9) -> 0 | I9: =D9 * E9 / 5 -> 0 | J9: =IF(C9=0, "Not Started", IF(E9<=2.5, "Weak (High Risk)", IF(E9<=3.5, "Medium", "Strong"))) -> 0
A10: Bit Manipulation | B10: =COUNTIF(tblMasterDatabase[Pattern], A10) -> 0 | C10: =COUNTIFS(tblMasterDatabase[Pattern], A10, tblMasterDatabase[Status], "<>") -> 0 | D10: =IF(B10=0, 0, C10/B10) -> 0 | E10: =IF(C10=0, 0, AVERAGEIFS(tblMasterDatabase[Confidence], tblMasterDatabase[Pattern], A10, tblMasterDatabase[Status], "<>")) -> 0 | F10: =IF(C10=0, 0, AVERAGEIFS(tblMasterDatabase[Time Taken], tblMasterDatabase[Pattern], A10, tblMasterDatabase[Status], "<>")) -> 0 | G10: =IF(C10=0, 0, COUNTIFS(tblMasterDatabase[Pattern], A10, tblMasterDatabase[Hint Used], "Yes") / C10) -> 0 | H10: =SUMIFS(tblMasterDatabase[Revision Count], tblMasterDatabase[Pattern], A10) -> 0 | I10: =D10 * E10 / 5 -> 0 | J10: =IF(C10=0, "Not Started", IF(E10<=2.5, "Weak (High Risk)", IF(E10<=3.5, "Medium", "Strong"))) -> 0
A11: DFS | B11: =COUNTIF(tblMasterDatabase[Pattern], A11) -> 0 | C11: =COUNTIFS(tblMasterDatabase[Pattern], A11, tblMasterDatabase[Status], "<>") -> 0 | D11: =IF(B11=0, 0, C11/B11) -> 0 | E11: =IF(C11=0, 0, AVERAGEIFS(tblMasterDatabase[Confidence], tblMasterDatabase[Pattern], A11, tblMasterDatabase[Status], "<>")) -> 0 | F11: =IF(C11=0, 0, AVERAGEIFS(tblMasterDatabase[Time Taken], tblMasterDatabase[Pattern], A11, tblMasterDatabase[Status], "<>")) -> 0 | G11: =IF(C11=0, 0, COUNTIFS(tblMasterDatabase[Pattern], A11, tblMasterDatabase[Hint Used], "Yes") / C11) -> 0 | H11: =SUMIFS(tblMasterDatabase[Revision Count], tblMasterDatabase[Pattern], A11) -> 0 | I11: =D11 * E11 / 5 -> 0 | J11: =IF(C11=0, "Not Started", IF(E11<=2.5, "Weak (High Risk)", IF(E11<=3.5, "Medium", "Strong"))) -> 0
A12: Dynamic Programming | B12: =COUNTIF(tblMasterDatabase[Pattern], A12) -> 0 | C12: =COUNTIFS(tblMasterDatabase[Pattern], A12, tblMasterDatabase[Status], "<>") -> 0 | D12: =IF(B12=0, 0, C12/B12) -> 0 | E12: =IF(C12=0, 0, AVERAGEIFS(tblMasterDatabase[Confidence], tblMasterDatabase[Pattern], A12, tblMasterDatabase[Status], "<>")) -> 0 | F12: =IF(C12=0, 0, AVERAGEIFS(tblMasterDatabase[Time Taken], tblMasterDatabase[Pattern], A12, tblMasterDatabase[Status], "<>")) -> 0 | G12: =IF(C12=0, 0, COUNTIFS(tblMasterDatabase[Pattern], A12, tblMasterDatabase[Hint Used], "Yes") / C12) -> 0 | H12: =SUMIFS(tblMasterDatabase[Revision Count], tblMasterDatabase[Pattern], A12) -> 0 | I12: =D12 * E12 / 5 -> 0 | J12: =IF(C12=0, "Not Started", IF(E12<=2.5, "Weak (High Risk)", IF(E12<=3.5, "Medium", "Strong"))) -> 0
A13: Greedy | B13: =COUNTIF(tblMasterDatabase[Pattern], A13) -> 0 | C13: =COUNTIFS(tblMasterDatabase[Pattern], A13, tblMasterDatabase[Status], "<>") -> 0 | D13: =IF(B13=0, 0, C13/B13) -> 0 | E13: =IF(C13=0, 0, AVERAGEIFS(tblMasterDatabase[Confidence], tblMasterDatabase[Pattern], A13, tblMasterDatabase[Status], "<>")) -> 0 | F13: =IF(C13=0, 0, AVERAGEIFS(tblMasterDatabase[Time Taken], tblMasterDatabase[Pattern], A13, tblMasterDatabase[Status], "<>")) -> 0 | G13: =IF(C13=0, 0, COUNTIFS(tblMasterDatabase[Pattern], A13, tblMasterDatabase[Hint Used], "Yes") / C13) -> 0 | H13: =SUMIFS(tblMasterDatabase[Revision Count], tblMasterDatabase[Pattern], A13) -> 0 | I13: =D13 * E13 / 5 -> 0 | J13: =IF(C13=0, "Not Started", IF(E13<=2.5, "Weak (High Risk)", IF(E13<=3.5, "Medium", "Strong"))) -> 0
A14: HashMap | B14: =COUNTIF(tblMasterDatabase[Pattern], A14) -> 0 | C14: =COUNTIFS(tblMasterDatabase[Pattern], A14, tblMasterDatabase[Status], "<>") -> 0 | D14: =IF(B14=0, 0, C14/B14) -> 0 | E14: =IF(C14=0, 0, AVERAGEIFS(tblMasterDatabase[Confidence], tblMasterDatabase[Pattern], A14, tblMasterDatabase[Status], "<>")) -> 0 | F14: =IF(C14=0, 0, AVERAGEIFS(tblMasterDatabase[Time Taken], tblMasterDatabase[Pattern], A14, tblMasterDatabase[Status], "<>")) -> 0 | G14: =IF(C14=0, 0, COUNTIFS(tblMasterDatabase[Pattern], A14, tblMasterDatabase[Hint Used], "Yes") / C14) -> 0 | H14: =SUMIFS(tblMasterDatabase[Revision Count], tblMasterDatabase[Pattern], A14) -> 0 | I14: =D14 * E14 / 5 -> 0 | J14: =IF(C14=0, "Not Started", IF(E14<=2.5, "Weak (High Risk)", IF(E14<=3.5, "Medium", "Strong"))) -> 0
A15: Heap | B15: =COUNTIF(tblMasterDatabase[Pattern], A15) -> 0 | C15: =COUNTIFS(tblMasterDatabase[Pattern], A15, tblMasterDatabase[Status], "<>") -> 0 | D15: =IF(B15=0, 0, C15/B15) -> 0 | E15: =IF(C15=0, 0, AVERAGEIFS(tblMasterDatabase[Confidence], tblMasterDatabase[Pattern], A15, tblMasterDatabase[Status], "<>")) -> 0 | F15: =IF(C15=0, 0, AVERAGEIFS(tblMasterDatabase[Time Taken], tblMasterDatabase[Pattern], A15, tblMasterDatabase[Status], "<>")) -> 0 | G15: =IF(C15=0, 0, COUNTIFS(tblMasterDatabase[Pattern], A15, tblMasterDatabase[Hint Used], "Yes") / C15) -> 0 | H15: =SUMIFS(tblMasterDatabase[Revision Count], tblMasterDatabase[Pattern], A15) -> 0 | I15: =D15 * E15 / 5 -> 0 | J15: =IF(C15=0, "Not Started", IF(E15<=2.5, "Weak (High Risk)", IF(E15<=3.5, "Medium", "Strong"))) -> 0
... A29: Union Find | B29: =COUNTIF(tblMasterDatabase[Pattern], A29) -> 0 | C29: =COUNTIFS(tblMasterDatabase[Pattern], A29, tblMasterDatabase[Status], "<>") -> 0 | D29: =IF(B29=0, 0, C29/B29) -> 0 | E29: =IF(C29=0, 0, AVERAGEIFS(tblMasterDatabase[Confidence], tblMasterDatabase[Pattern], A29, tblMasterDatabase[Status], "<>")) -> 0 | F29: =IF(C29=0, 0, AVERAGEIFS(tblMasterDatabase[Time Taken], tblMasterDatabase[Pattern], A29, tblMasterDatabase[Status], "<>")) -> 0 | G29: =IF(C29=0, 0, COUNTIFS(tblMasterDatabase[Pattern], A29, tblMasterDatabase[Hint Used], "Yes") / C29) -> 0 | H29: =SUMIFS(tblMasterDatabase[Revision Count], tblMasterDatabase[Pattern], A29) -> 0 | I29: =D29 * E29 / 5 -> 0 | J29: =IF(C29=0, "Not Started", IF(E29<=2.5, "Weak (High Risk)", IF(E29<=3.5, "Medium", "Strong"))) -> 0

Sheet Company Readiness
B2: Company-Specific AI Placement Readiness Engine
G3: Company Name | H3: Total Tags | I3: Solved | J3: Completion % | K3: Revision % | L3: Average Confidence | M3: High ROI Completion % | N3: Mock OA Average | O3: Readiness Score | P3: Status | Q3: Strength | R3: Weakness | S3: Suggested Revision
B4: Target Company Selector: | C4: JPMC | G4: Accenture | H4: =COUNTIF(tblMasterDatabase[Company Tags], "*"&G4&"*") -> 0 | I4: =COUNTIFS(tblMasterDatabase[Company Tags], "*"&G4&"*", tblMasterDatabase[Status], "<>") -> 0 | J4: =IF(H4=0, 0, I4/H4) -> 0 | K4: =IF(I4=0, 0, COUNTIFS(tblMasterDatabase[Company Tags], "*"&G4&"*", tblMasterDatabase[Status], "<>", tblMasterDatabase[Next Revision], ">="&TODAY()) / I4) -> 0 | L4: =IF(I4=0, 0, AVERAGEIFS(tblMasterDatabase[Confidence], tblMasterDatabase[Company Tags], "*"&G4&"*", tblMasterDatabase[Status], "<>")) -> 0 | M4: =IF(COUNTIFS(tblMasterDatabase[Company Tags], "*"&G4&"*", tblMasterDatabase[ROI], ">=8")=0, 1, COUNTIFS(tblMasterDatabase[Company Tags], "*"&G4&"*", tblMasterDatabase[ROI], ">=8", tblMasterDatabase[Status], "<>") / COUNTIFS(tblMasterDatabase[Company Tags], "*"&G4&"*", tblMasterDatabase[ROI], ">=8")) -> 0 | N4: =IF(COUNTIF(tblMockOA[Company], G4)=0, 70%, AVERAGEIF(tblMockOA[Company], G4, tblMockOA[Score])) -> 0 | O4: =35% * K4 + 25% * J4 + 20% * M4 + 10% * (L4/5) + 10% * N4 -> 0 | P4: =IF(O4<0.6, "Needs Work", IF(O4<0.75, "Improving", IF(O4<0.9, "Placement Ready", "Strong Candidate"))) -> 0 | Q4: =IF(INDEX(tblPatternTracker[Completion %], MATCH("Arrays", tblPatternTracker[Pattern Name], 0)) >= INDEX(tblPatternTracker[Completion %], MATCH("HashMap", tblPatternTracker[Pattern Name], 0)), "Arrays", "HashMap") -> 0 | R4: =IF(INDEX(tblPatternTracker[Completion %], MATCH("Arrays", tblPatternTracker[Pattern Name], 0)) < INDEX(tblPatternTracker[Completion %], MATCH("HashMap", tblPatternTracker[Pattern Name], 0)), "Arrays", "HashMap") -> 0 | S4: {=IFERROR(TEXTJOIN(", ", TRUE, _xlfn.TAKE(_xlfn._xlws.FILTER(tblMasterDatabase[Problem Name], (ISNUMBER(SEARCH(G4, tblMasterDatabase[Company Tags]))) * (tblMasterDatabase[Next Revision]<=TODAY())), 2)), "All Caught Up!")} -> 0
G5: Infosys | H5: =COUNTIF(tblMasterDatabase[Company Tags], "*"&G5&"*") -> 0 | I5: =COUNTIFS(tblMasterDatabase[Company Tags], "*"&G5&"*", tblMasterDatabase[Status], "<>") -> 0 | J5: =IF(H5=0, 0, I5/H5) -> 0 | K5: =IF(I5=0, 0, COUNTIFS(tblMasterDatabase[Company Tags], "*"&G5&"*", tblMasterDatabase[Status], "<>", tblMasterDatabase[Next Revision], ">="&TODAY()) / I5) -> 0 | L5: =IF(I5=0, 0, AVERAGEIFS(tblMasterDatabase[Confidence], tblMasterDatabase[Company Tags], "*"&G5&"*", tblMasterDatabase[Status], "<>")) -> 0 | M5: =IF(COUNTIFS(tblMasterDatabase[Company Tags], "*"&G5&"*", tblMasterDatabase[ROI], ">=8")=0, 1, COUNTIFS(tblMasterDatabase[Company Tags], "*"&G5&"*", tblMasterDatabase[ROI], ">=8", tblMasterDatabase[Status], "<>") / COUNTIFS(tblMasterDatabase[Company Tags], "*"&G5&"*", tblMasterDatabase[ROI], ">=8")) -> 0 | N5: =IF(COUNTIF(tblMockOA[Company], G5)=0, 70%, AVERAGEIF(tblMockOA[Company], G5, tblMockOA[Score])) -> 0 | O5: =35% * K5 + 25% * J5 + 20% * M5 + 10% * (L5/5) + 10% * N5 -> 0 | P5: =IF(O5<0.6, "Needs Work", IF(O5<0.75, "Improving", IF(O5<0.9, "Placement Ready", "Strong Candidate"))) -> 0 | Q5: =IF(INDEX(tblPatternTracker[Completion %], MATCH("HashMap", tblPatternTracker[Pattern Name], 0)) >= INDEX(tblPatternTracker[Completion %], MATCH("Two Pointer", tblPatternTracker[Pattern Name], 0)), "HashMap", "Two Pointer") -> 0 | R5: =IF(INDEX(tblPatternTracker[Completion %], MATCH("HashMap", tblPatternTracker[Pattern Name], 0)) < INDEX(tblPatternTracker[Completion %], MATCH("Two Pointer", tblPatternTracker[Pattern Name], 0)), "HashMap", "Two Pointer") -> 0 | S5: {=IFERROR(TEXTJOIN(", ", TRUE, _xlfn.TAKE(_xlfn._xlws.FILTER(tblMasterDatabase[Problem Name], (ISNUMBER(SEARCH(G5, tblMasterDatabase[Company Tags]))) * (tblMasterDatabase[Next Revision]<=TODAY())), 2)), "All Caught Up!")} -> 0
B6: ESTIMATED READINESS | C6: =IFERROR(INDEX(tblCompanyReadiness[Readiness Score], MATCH(C4, tblCompanyReadiness[Company Name], 0)), 0) -> 0 | G6: Capgemini | H6: =COUNTIF(tblMasterDatabase[Company Tags], "*"&G6&"*") -> 0 | I6: =COUNTIFS(tblMasterDatabase[Company Tags], "*"&G6&"*", tblMasterDatabase[Status], "<>") -> 0 | J6: =IF(H6=0, 0, I6/H6) -> 0 | K6: =IF(I6=0, 0, COUNTIFS(tblMasterDatabase[Company Tags], "*"&G6&"*", tblMasterDatabase[Status], "<>", tblMasterDatabase[Next Revision], ">="&TODAY()) / I6) -> 0 | L6: =IF(I6=0, 0, AVERAGEIFS(tblMasterDatabase[Confidence], tblMasterDatabase[Company Tags], "*"&G6&"*", tblMasterDatabase[Status], "<>")) -> 0 | M6: =IF(COUNTIFS(tblMasterDatabase[Company Tags], "*"&G6&"*", tblMasterDatabase[ROI], ">=8")=0, 1, COUNTIFS(tblMasterDatabase[Company Tags], "*"&G6&"*", tblMasterDatabase[ROI], ">=8", tblMasterDatabase[Status], "<>") / COUNTIFS(tblMasterDatabase[Company Tags], "*"&G6&"*", tblMasterDatabase[ROI], ">=8")) -> 0 | N6: =IF(COUNTIF(tblMockOA[Company], G6)=0, 70%, AVERAGEIF(tblMockOA[Company], G6, tblMockOA[Score])) -> 0 | O6: =35% * K6 + 25% * J6 + 20% * M6 + 10% * (L6/5) + 10% * N6 -> 0 | P6: =IF(O6<0.6, "Needs Work", IF(O6<0.75, "Improving", IF(O6<0.9, "Placement Ready", "Strong Candidate"))) -> 0 | Q6: =IF(INDEX(tblPatternTracker[Completion %], MATCH("Linked List", tblPatternTracker[Pattern Name], 0)) >= INDEX(tblPatternTracker[Completion %], MATCH("Two Pointer", tblPatternTracker[Pattern Name], 0)), "Linked List", "Two Pointer") -> 0 | R6: =IF(INDEX(tblPatternTracker[Completion %], MATCH("Linked List", tblPatternTracker[Pattern Name], 0)) < INDEX(tblPatternTracker[Completion %], MATCH("Two Pointer", tblPatternTracker[Pattern Name], 0)), "Linked List", "Two Pointer") -> 0 | S6: {=IFERROR(TEXTJOIN(", ", TRUE, _xlfn.TAKE(_xlfn._xlws.FILTER(tblMasterDatabase[Problem Name], (ISNUMBER(SEARCH(G6, tblMasterDatabase[Company Tags]))) * (tblMasterDatabase[Next Revision]<=TODAY())), 2)), "All Caught Up!")} -> 0
G7: Cognizant | H7: =COUNTIF(tblMasterDatabase[Company Tags], "*"&G7&"*") -> 0 | I7: =COUNTIFS(tblMasterDatabase[Company Tags], "*"&G7&"*", tblMasterDatabase[Status], "<>") -> 0 | J7: =IF(H7=0, 0, I7/H7) -> 0 | K7: =IF(I7=0, 0, COUNTIFS(tblMasterDatabase[Company Tags], "*"&G7&"*", tblMasterDatabase[Status], "<>", tblMasterDatabase[Next Revision], ">="&TODAY()) / I7) -> 0 | L7: =IF(I7=0, 0, AVERAGEIFS(tblMasterDatabase[Confidence], tblMasterDatabase[Company Tags], "*"&G7&"*", tblMasterDatabase[Status], "<>")) -> 0 | M7: =IF(COUNTIFS(tblMasterDatabase[Company Tags], "*"&G7&"*", tblMasterDatabase[ROI], ">=8")=0, 1, COUNTIFS(tblMasterDatabase[Company Tags], "*"&G7&"*", tblMasterDatabase[ROI], ">=8", tblMasterDatabase[Status], "<>") / COUNTIFS(tblMasterDatabase[Company Tags], "*"&G7&"*", tblMasterDatabase[ROI], ">=8")) -> 0 | N7: =IF(COUNTIF(tblMockOA[Company], G7)=0, 70%, AVERAGEIF(tblMockOA[Company], G7, tblMockOA[Score])) -> 0 | O7: =35% * K7 + 25% * J7 + 20% * M7 + 10% * (L7/5) + 10% * N7 -> 0 | P7: =IF(O7<0.6, "Needs Work", IF(O7<0.75, "Improving", IF(O7<0.9, "Placement Ready", "Strong Candidate"))) -> 0 | Q7: =IF(INDEX(tblPatternTracker[Completion %], MATCH("Sliding Window", tblPatternTracker[Pattern Name], 0)) >= INDEX(tblPatternTracker[Completion %], MATCH("Monotonic Stack", tblPatternTracker[Pattern Name], 0)), "Sliding Window", "Monotonic Stack") -> 0 | R7: =IF(INDEX(tblPatternTracker[Completion %], MATCH("Sliding Window", tblPatternTracker[Pattern Name], 0)) < INDEX(tblPatternTracker[Completion %], MATCH("Monotonic Stack", tblPatternTracker[Pattern Name], 0)), "Sliding Window", "Monotonic Stack") -> 0 | S7: {=IFERROR(TEXTJOIN(", ", TRUE, _xlfn.TAKE(_xlfn._xlws.FILTER(tblMasterDatabase[Problem Name], (ISNUMBER(SEARCH(G7, tblMasterDatabase[Company Tags]))) * (tblMasterDatabase[Next Revision]<=TODAY())), 2)), "All Caught Up!")} -> 0
B8: PROJECTED READINESS | C8: =IFERROR(C6 + (1-C6)*0.4, 0) -> 0 | G8: Deloitte | H8: =COUNTIF(tblMasterDatabase[Company Tags], "*"&G8&"*") -> 0 | I8: =COUNTIFS(tblMasterDatabase[Company Tags], "*"&G8&"*", tblMasterDatabase[Status], "<>") -> 0 | J8: =IF(H8=0, 0, I8/H8) -> 0 | K8: =IF(I8=0, 0, COUNTIFS(tblMasterDatabase[Company Tags], "*"&G8&"*", tblMasterDatabase[Status], "<>", tblMasterDatabase[Next Revision], ">="&TODAY()) / I8) -> 0 | L8: =IF(I8=0, 0, AVERAGEIFS(tblMasterDatabase[Confidence], tblMasterDatabase[Company Tags], "*"&G8&"*", tblMasterDatabase[Status], "<>")) -> 0 | M8: =IF(COUNTIFS(tblMasterDatabase[Company Tags], "*"&G8&"*", tblMasterDatabase[ROI], ">=8")=0, 1, COUNTIFS(tblMasterDatabase[Company Tags], "*"&G8&"*", tblMasterDatabase[ROI], ">=8", tblMasterDatabase[Status], "<>") / COUNTIFS(tblMasterDatabase[Company Tags], "*"&G8&"*", tblMasterDatabase[ROI], ">=8")) -> 0 | N8: =IF(COUNTIF(tblMockOA[Company], G8)=0, 70%, AVERAGEIF(tblMockOA[Company], G8, tblMockOA[Score])) -> 0 | O8: =35% * K8 + 25% * J8 + 20% * M8 + 10% * (L8/5) + 10% * N8 -> 0 | P8: =IF(O8<0.6, "Needs Work", IF(O8<0.75, "Improving", IF(O8<0.9, "Placement Ready", "Strong Candidate"))) -> 0 | Q8: =IF(INDEX(tblPatternTracker[Completion %], MATCH("Binary Search", tblPatternTracker[Pattern Name], 0)) >= INDEX(tblPatternTracker[Completion %], MATCH("Greedy", tblPatternTracker[Pattern Name], 0)), "Binary Search", "Greedy") -> 0 | R8: =IF(INDEX(tblPatternTracker[Completion %], MATCH("Binary Search", tblPatternTracker[Pattern Name], 0)) < INDEX(tblPatternTracker[Completion %], MATCH("Greedy", tblPatternTracker[Pattern Name], 0)), "Binary Search", "Greedy") -> 0 | S8: {=IFERROR(TEXTJOIN(", ", TRUE, _xlfn.TAKE(_xlfn._xlws.FILTER(tblMasterDatabase[Problem Name], (ISNUMBER(SEARCH(G8, tblMasterDatabase[Company Tags]))) * (tblMasterDatabase[Next Revision]<=TODAY())), 2)), "All Caught Up!")} -> 0
G9: EY | H9: =COUNTIF(tblMasterDatabase[Company Tags], "*"&G9&"*") -> 0 | I9: =COUNTIFS(tblMasterDatabase[Company Tags], "*"&G9&"*", tblMasterDatabase[Status], "<>") -> 0 | J9: =IF(H9=0, 0, I9/H9) -> 0 | K9: =IF(I9=0, 0, COUNTIFS(tblMasterDatabase[Company Tags], "*"&G9&"*", tblMasterDatabase[Status], "<>", tblMasterDatabase[Next Revision], ">="&TODAY()) / I9) -> 0 | L9: =IF(I9=0, 0, AVERAGEIFS(tblMasterDatabase[Confidence], tblMasterDatabase[Company Tags], "*"&G9&"*", tblMasterDatabase[Status], "<>")) -> 0 | M9: =IF(COUNTIFS(tblMasterDatabase[Company Tags], "*"&G9&"*", tblMasterDatabase[ROI], ">=8")=0, 1, COUNTIFS(tblMasterDatabase[Company Tags], "*"&G9&"*", tblMasterDatabase[ROI], ">=8", tblMasterDatabase[Status], "<>") / COUNTIFS(tblMasterDatabase[Company Tags], "*"&G9&"*", tblMasterDatabase[ROI], ">=8")) -> 0 | N9: =IF(COUNTIF(tblMockOA[Company], G9)=0, 70%, AVERAGEIF(tblMockOA[Company], G9, tblMockOA[Score])) -> 0 | O9: =35% * K9 + 25% * J9 + 20% * M9 + 10% * (L9/5) + 10% * N9 -> 0 | P9: =IF(O9<0.6, "Needs Work", IF(O9<0.75, "Improving", IF(O9<0.9, "Placement Ready", "Strong Candidate"))) -> 0 | Q9: =IF(INDEX(tblPatternTracker[Completion %], MATCH("Prefix Sum", tblPatternTracker[Pattern Name], 0)) >= INDEX(tblPatternTracker[Completion %], MATCH("HashMap", tblPatternTracker[Pattern Name], 0)), "Prefix Sum", "HashMap") -> 0 | R9: =IF(INDEX(tblPatternTracker[Completion %], MATCH("Prefix Sum", tblPatternTracker[Pattern Name], 0)) < INDEX(tblPatternTracker[Completion %], MATCH("HashMap", tblPatternTracker[Pattern Name], 0)), "Prefix Sum", "HashMap") -> 0 | S9: {=IFERROR(TEXTJOIN(", ", TRUE, _xlfn.TAKE(_xlfn._xlws.FILTER(tblMasterDatabase[Problem Name], (ISNUMBER(SEARCH(G9, tblMasterDatabase[Company Tags]))) * (tblMasterDatabase[Next Revision]<=TODAY())), 2)), "All Caught Up!")} -> 0
B10: Primary Strength Pattern: | C10: =IFERROR(INDEX(tblCompanyReadiness[Strength], MATCH(C4, tblCompanyReadiness[Company Name], 0)), "N/A") -> 0 | G10: Oracle | H10: =COUNTIF(tblMasterDatabase[Company Tags], "*"&G10&"*") -> 0 | I10: =COUNTIFS(tblMasterDatabase[Company Tags], "*"&G10&"*", tblMasterDatabase[Status], "<>") -> 0 | J10: =IF(H10=0, 0, I10/H10) -> 0 | K10: =IF(I10=0, 0, COUNTIFS(tblMasterDatabase[Company Tags], "*"&G10&"*", tblMasterDatabase[Status], "<>", tblMasterDatabase[Next Revision], ">="&TODAY()) / I10) -> 0 | L10: =IF(I10=0, 0, AVERAGEIFS(tblMasterDatabase[Confidence], tblMasterDatabase[Company Tags], "*"&G10&"*", tblMasterDatabase[Status], "<>")) -> 0 | M10: =IF(COUNTIFS(tblMasterDatabase[Company Tags], "*"&G10&"*", tblMasterDatabase[ROI], ">=8")=0, 1, COUNTIFS(tblMasterDatabase[Company Tags], "*"&G10&"*", tblMasterDatabase[ROI], ">=8", tblMasterDatabase[Status], "<>") / COUNTIFS(tblMasterDatabase[Company Tags], "*"&G10&"*", tblMasterDatabase[ROI], ">=8")) -> 0 | N10: =IF(COUNTIF(tblMockOA[Company], G10)=0, 70%, AVERAGEIF(tblMockOA[Company], G10, tblMockOA[Score])) -> 0 | O10: =35% * K10 + 25% * J10 + 20% * M10 + 10% * (L10/5) + 10% * N10 -> 0 | P10: =IF(O10<0.6, "Needs Work", IF(O10<0.75, "Improving", IF(O10<0.9, "Placement Ready", "Strong Candidate"))) -> 0 | Q10: =IF(INDEX(tblPatternTracker[Completion %], MATCH("BST", tblPatternTracker[Pattern Name], 0)) >= INDEX(tblPatternTracker[Completion %], MATCH("Heap", tblPatternTracker[Pattern Name], 0)), "BST", "Heap") -> 0 | R10: =IF(INDEX(tblPatternTracker[Completion %], MATCH("BST", tblPatternTracker[Pattern Name], 0)) < INDEX(tblPatternTracker[Completion %], MATCH("Heap", tblPatternTracker[Pattern Name], 0)), "BST", "Heap") -> 0 | S10: {=IFERROR(TEXTJOIN(", ", TRUE, _xlfn.TAKE(_xlfn._xlws.FILTER(tblMasterDatabase[Problem Name], (ISNUMBER(SEARCH(G10, tblMasterDatabase[Company Tags]))) * (tblMasterDatabase[Next Revision]<=TODAY())), 2)), "All Caught Up!")} -> 0
B11: Primary Weakness Pattern: | C11: =IFERROR(INDEX(tblCompanyReadiness[Weakness], MATCH(C4, tblCompanyReadiness[Company Name], 0)), "N/A") -> 0 | G11: JPMC | H11: =COUNTIF(tblMasterDatabase[Company Tags], "*"&G11&"*") -> 0 | I11: =COUNTIFS(tblMasterDatabase[Company Tags], "*"&G11&"*", tblMasterDatabase[Status], "<>") -> 0 | J11: =IF(H11=0, 0, I11/H11) -> 0 | K11: =IF(I11=0, 0, COUNTIFS(tblMasterDatabase[Company Tags], "*"&G11&"*", tblMasterDatabase[Status], "<>", tblMasterDatabase[Next Revision], ">="&TODAY()) / I11) -> 0 | L11: =IF(I11=0, 0, AVERAGEIFS(tblMasterDatabase[Confidence], tblMasterDatabase[Company Tags], "*"&G11&"*", tblMasterDatabase[Status], "<>")) -> 0 | M11: =IF(COUNTIFS(tblMasterDatabase[Company Tags], "*"&G11&"*", tblMasterDatabase[ROI], ">=8")=0, 1, COUNTIFS(tblMasterDatabase[Company Tags], "*"&G11&"*", tblMasterDatabase[ROI], ">=8", tblMasterDatabase[Status], "<>") / COUNTIFS(tblMasterDatabase[Company Tags], "*"&G11&"*", tblMasterDatabase[ROI], ">=8")) -> 0 | N11: =IF(COUNTIF(tblMockOA[Company], G11)=0, 70%, AVERAGEIF(tblMockOA[Company], G11, tblMockOA[Score])) -> 0 | O11: =35% * K11 + 25% * J11 + 20% * M11 + 10% * (L11/5) + 10% * N11 -> 0 | P11: =IF(O11<0.6, "Needs Work", IF(O11<0.75, "Improving", IF(O11<0.9, "Placement Ready", "Strong Candidate"))) -> 0 | Q11: =IF(INDEX(tblPatternTracker[Completion %], MATCH("Trees", tblPatternTracker[Pattern Name], 0)) >= INDEX(tblPatternTracker[Completion %], MATCH("Dynamic Programming", tblPatternTracker[Pattern Name], 0)), "Trees", "Dynamic Programming") -> 0 | R11: =IF(INDEX(tblPatternTracker[Completion %], MATCH("Trees", tblPatternTracker[Pattern Name], 0)) < INDEX(tblPatternTracker[Completion %], MATCH("Dynamic Programming", tblPatternTracker[Pattern Name], 0)), "Trees", "Dynamic Programming") -> 0 | S11: {=IFERROR(TEXTJOIN(", ", TRUE, _xlfn.TAKE(_xlfn._xlws.FILTER(tblMasterDatabase[Problem Name], (ISNUMBER(SEARCH(G11, tblMasterDatabase[Company Tags]))) * (tblMasterDatabase[Next Revision]<=TODAY())), 2)), "All Caught Up!")} -> 0
G12: LTIMindtree | H12: =COUNTIF(tblMasterDatabase[Company Tags], "*"&G12&"*") -> 0 | I12: =COUNTIFS(tblMasterDatabase[Company Tags], "*"&G12&"*", tblMasterDatabase[Status], "<>") -> 0 | J12: =IF(H12=0, 0, I12/H12) -> 0 | K12: =IF(I12=0, 0, COUNTIFS(tblMasterDatabase[Company Tags], "*"&G12&"*", tblMasterDatabase[Status], "<>", tblMasterDatabase[Next Revision], ">="&TODAY()) / I12) -> 0 | L12: =IF(I12=0, 0, AVERAGEIFS(tblMasterDatabase[Confidence], tblMasterDatabase[Company Tags], "*"&G12&"*", tblMasterDatabase[Status], "<>")) -> 0 | M12: =IF(COUNTIFS(tblMasterDatabase[Company Tags], "*"&G12&"*", tblMasterDatabase[ROI], ">=8")=0, 1, COUNTIFS(tblMasterDatabase[Company Tags], "*"&G12&"*", tblMasterDatabase[ROI], ">=8", tblMasterDatabase[Status], "<>") / COUNTIFS(tblMasterDatabase[Company Tags], "*"&G12&"*", tblMasterDatabase[ROI], ">=8")) -> 0 | N12: =IF(COUNTIF(tblMockOA[Company], G12)=0, 70%, AVERAGEIF(tblMockOA[Company], G12, tblMockOA[Score])) -> 0 | O12: =35% * K12 + 25% * J12 + 20% * M12 + 10% * (L12/5) + 10% * N12 -> 0 | P12: =IF(O12<0.6, "Needs Work", IF(O12<0.75, "Improving", IF(O12<0.9, "Placement Ready", "Strong Candidate"))) -> 0 | Q12: =IF(INDEX(tblPatternTracker[Completion %], MATCH("Arrays", tblPatternTracker[Pattern Name], 0)) >= INDEX(tblPatternTracker[Completion %], MATCH("DFS", tblPatternTracker[Pattern Name], 0)), "Arrays", "DFS") -> 0 | R12: =IF(INDEX(tblPatternTracker[Completion %], MATCH("Arrays", tblPatternTracker[Pattern Name], 0)) < INDEX(tblPatternTracker[Completion %], MATCH("DFS", tblPatternTracker[Pattern Name], 0)), "Arrays", "DFS") -> 0 | S12: {=IFERROR(TEXTJOIN(", ", TRUE, _xlfn.TAKE(_xlfn._xlws.FILTER(tblMasterDatabase[Problem Name], (ISNUMBER(SEARCH(G12, tblMasterDatabase[Company Tags]))) * (tblMasterDatabase[Next Revision]<=TODAY())), 2)), "All Caught Up!")} -> 0
B13: Recommended Prep Tasks to Reach Target: | G13: Virtusa | H13: =COUNTIF(tblMasterDatabase[Company Tags], "*"&G13&"*") -> 0 | I13: =COUNTIFS(tblMasterDatabase[Company Tags], "*"&G13&"*", tblMasterDatabase[Status], "<>") -> 0 | J13: =IF(H13=0, 0, I13/H13) -> 0 | K13: =IF(I13=0, 0, COUNTIFS(tblMasterDatabase[Company Tags], "*"&G13&"*", tblMasterDatabase[Status], "<>", tblMasterDatabase[Next Revision], ">="&TODAY()) / I13) -> 0 | L13: =IF(I13=0, 0, AVERAGEIFS(tblMasterDatabase[Confidence], tblMasterDatabase[Company Tags], "*"&G13&"*", tblMasterDatabase[Status], "<>")) -> 0 | M13: =IF(COUNTIFS(tblMasterDatabase[Company Tags], "*"&G13&"*", tblMasterDatabase[ROI], ">=8")=0, 1, COUNTIFS(tblMasterDatabase[Company Tags], "*"&G13&"*", tblMasterDatabase[ROI], ">=8", tblMasterDatabase[Status], "<>") / COUNTIFS(tblMasterDatabase[Company Tags], "*"&G13&"*", tblMasterDatabase[ROI], ">=8")) -> 0 | N13: =IF(COUNTIF(tblMockOA[Company], G13)=0, 70%, AVERAGEIF(tblMockOA[Company], G13, tblMockOA[Score])) -> 0 | O13: =35% * K13 + 25% * J13 + 20% * M13 + 10% * (L13/5) + 10% * N13 -> 0 | P13: =IF(O13<0.6, "Needs Work", IF(O13<0.75, "Improving", IF(O13<0.9, "Placement Ready", "Strong Candidate"))) -> 0 | Q13: =IF(INDEX(tblPatternTracker[Completion %], MATCH("Graphs", tblPatternTracker[Pattern Name], 0)) >= INDEX(tblPatternTracker[Completion %], MATCH("Queue", tblPatternTracker[Pattern Name], 0)), "Graphs", "Queue") -> 0 | R13: =IF(INDEX(tblPatternTracker[Completion %], MATCH("Graphs", tblPatternTracker[Pattern Name], 0)) < INDEX(tblPatternTracker[Completion %], MATCH("Queue", tblPatternTracker[Pattern Name], 0)), "Graphs", "Queue") -> 0 | S13: {=IFERROR(TEXTJOIN(", ", TRUE, _xlfn.TAKE(_xlfn._xlws.FILTER(tblMasterDatabase[Problem Name], (ISNUMBER(SEARCH(G13, tblMasterDatabase[Company Tags]))) * (tblMasterDatabase[Next Revision]<=TODAY())), 2)), "All Caught Up!")} -> 0
B14: ID | C14: Problem Name | D14: Pattern | E14: Difficulty | F14: ROI
B15: {=IFERROR(_xlfn.TAKE(_xlfn.SORTBY(_xlfn._xlws.FILTER(_xlfn.CHOOSECOLS(tblMasterDatabase, 1, 2, 4, 5, 7), (tblMasterDatabase[Status]="") * (ISNUMBER(SEARCH(C4, tblMasterDatabase[Company Tags])))), _xlfn._xlws.FILTER(tblMasterDatabase[ROI], (tblMasterDatabase[Status]="") * (ISNUMBER(SEARCH(C4, tblMasterDatabase[Company Tags])))), -1), 4), "All caught up for this company!")} -> 0

Sheet Mock OA Tracker
A1: Online Assessment (OA) Simulation Log & Performance
B3: AVERAGE SCORE | D3: BEST SCORE | F3: WORST SCORE | H3: AVERAGE TIME | J3: AVERAGE ACCURACY
